Workbook

Sheet Leyenda y Criterios
A1: TFM 14MBID — Plantilla de Extraccion para Revision Bibliografica | F1: Fecha actualizacion | H1: 46258
A2: Estimacion de Desalineacion Fisiologica en Insuficiencia Suprarrenal mediante Wearables
A4: COMO USAR ESTA PLANTILLA
A5: 1. Registra cada estudio candidato en la pestana 'Extraccion_Estudios', una fila por estudio.
A6: 2. Aplica primero los criterios de Inclusion/Exclusion (columnas H-K). Si el estudio se excluye, indica el motivo (E1-E6) y no completes las columnas de calidad.
A7: 3. Si el estudio se incluye, puntua cada uno de los 12 criterios de calidad consolidados (columnas N-Y) con escala 0-2 (ver esta hoja, seccion CRITERIOS DE CALIDAD).
A8: 4. La columna 'Puntuacion_Total' se calcula automaticamente (suma de los 12 criterios, maximo 24).
A9: 5. Usa la pestana 'Flujo_PRISMA' para llevar el conteo de estudios identificados, cribados, excluidos e incluidos por base de datos.
A10: 6. Un estudio con 1-2 criterios en 0 puede incluirse igualmente si es la unica fuente disponible para un constructo (especialmente en RQ4): documentalo en 'Notas_Limitaciones', no lo descartes automaticamente.
A11: 7. Estos 12 criterios son la version consolidada tras fusionar 8 pares redundantes de una lista ampliada de 20 propuestas; no reintroducir los criterios eliminados (12,13,14,15,16,17,19,20 de esa lista) como columnas nuevas, ya que duplicarian constructos.
A13: ESCALA DE PUNTUACION (criterios de calidad, columnas N-Y)
A14: 0 | B14: No cumple / no reportado
A15: 1 | B15: Cumple parcialmente / reportado de forma incompleta
A16: 2 | B16: Cumple completamente / reportado con claridad y detalle
A18: LOS 12 CRITERIOS DE CALIDAD (version consolidada)
A19: Cod. | B19: Criterio | C19: Que evalua | D19: Por que es relevante
A20: C1 | B20: Trazabilidad de la muestra/dataset y protocolo de induccion de estres | C20: Tamano muestral, criterios de seleccion, caracteristicas de poblacion y, en datasets (WESAD/SWELL), protocolo de captura, anotacion y metodo de induccion de estres (TSST, Stroop u otro validado). | D20: RQ3: sin trazabilidad completa del protocolo de induccion no puedes argumentar validez de dominio cruzado, solo asumirla.
A21: C2 | B21: Validez de la medida de referencia (ground truth) endocrino | C21: Si el marcador endocrino de referencia (cortisol salival/serico, ACTH) esta bien medido, con timing correcto respecto al ritmo circadiano. | D21: RQ4: un ground truth debil contamina toda la cadena de inferencia StressLoad-Demand.
A22: C3 | B22: Consistencia temporal y plausibilidad fisiologica SNA-HPA | C22: Si controla el desfase (lag) entre respuesta autonomica (segundos) y respuesta HPA (minutos-horas), apoyado en mecanismos fisiologicos documentados. | D22: Filtra estudios estadisticamente significativos pero fisiologicamente inconsistentes con la cinetica diferencial SNA/HPA.
A23: C4 | B23: Distincion entre variable observada (proxy) y variable inferida (latente) | C23: Si diferencia explicitamente senales medibles (HR, HRV, EDA, temperatura) del estado fisiologico latente subyacente (activacion simpatica, carga alostatica). | D23: Protege el principio de que Demand(t) es una variable latente no observable; excluye estudios que afirman medir estres directamente con un wearable.
A24: C5 | B24: Transparencia e interpretabilidad del modelo de ML | C24: Si reporta no solo metricas de rendimiento (accuracy, F1, AUC) sino mecanismos de explicabilidad (SHAP, LIME, feature importance, reglas de decision). | D24: El proyecto prioriza interpretabilidad sobre precision maxima; sin explicabilidad el modelo no es defendible clinicamente.
A25: C6 | B25: Validacion externa/cruzada robusta frente a fuga de datos | C25: Si el modelo se valida en muestra distinta al entrenamiento, con estrategias que evitan data leakage entre sujetos (GroupKFold, Leave-One-Subject-Out). | D25: RQ3: un split aleatorio intra-sujeto infla artificialmente el rendimiento y oculta el riesgo real de generalizacion.
A26: C7 | B26: Especificacion cuantitativa y rigor de parametros farmacocineticos | C26: Si reporta valores numericos concretos (ka, ke, Tmax, Cmax, biodisponibilidad, vida media) para hidrocortisona oral, no solo descripcion cualitativa. | D26: RQ10: necesitas parametros reales y rangos fisiologicamente realistas para calibrar el modelo monocompartimental.
A27: C8 | B27: Variabilidad inter/intraindividual y manejo de baselines individualizados | C27: Si reporta rangos de variacion entre sujetos y dentro del mismo sujeto; si emplea normalizacion o baseline individualizado (z-score intra-sujeto). | D27: El sistema opera sobre baselines personalizados; sin esto no se puede justificar la personalizacion ni calibrar la incertidumbre en Coverage(t)/Demand(t).
A28: C9 | B28: Alineacion con soporte a la decision, no diagnostico autonomo | C28: Si se encuadra explicitamente como CDSS / contextual risk estimation, con limites claros de responsabilidad, o como herramienta diagnostica/predictiva autonoma. | D28: Protege el framing obligatorio del TFM; evita contaminacion conceptual por asociacion con literatura de diagnostico o dosificacion automatica.
A29: C10 | B29: Transparencia en las limitaciones declaradas por los autores | C29: Si incluye una seccion de limitaciones sustantiva (sesgos de muestra, generalizacion, validez ecologica) o las omite/minimiza. | D29: Senal indirecta de rigor; filtro de sesgo comercial, especialmente relevante en el dominio wearable-consumer.
A30: C11 | B30: Trazabilidad del algoritmo de fusion y calculo del mismatch | C30: Si define formalmente las funciones o reglas logicas para calcular el desacople entre dos series temporales heterogeneas (una inferida, una calculada). | D30: Sostiene Risk(t) = Demand(t) - Coverage(t); aporta precedentes sobre alineacion temporal de variables latentes sin falsas alarmas por ruido.
A31: C12 | B31: Adecuacion del diseno de validacion y analisis de sensibilidad | C31: Si distingue validacion funcional/robustez (escenarios sinteticos) de validacion de eficacia clinica real, e incluye analisis de sensibilidad frente a ruido y variacion de parametros. | D31: Espejo de la estrategia de validacion del TFM (RQ7); sostiene que la validacion sintetica prueba robustez algoritmica, no eficacia clinica.
A33: MOTIVOS DE EXCLUSION (usar codigo en columna 'Motivo_Exclusion')
A34: Cod. | B34: Motivo
A35: E1 | B35: Duplicado de estudio ya considerado
A36: E2 | B36: Formato no academico / sin revision por pares (editorial, web, resumen sin articulo completo)
A37: E3 | B37: Centrado exclusivamente en diagnostico clinico de insuficiencia suprarrenal, sin relacion con wearables/monitorizacion
A38: E4 | B38: Cortisol/ACTH como unico outcome, sin variable autonomica periferica asociada
A39: E5 | B39: Financiacion no declarada del fabricante del dispositivo evaluado, sin validacion independiente
A40: E6 | B40: Literatura de marketing / whitepaper de producto sin metodologia cientifica trazable
A41: OTRO | B41: Otro motivo (especificar en Notas_Limitaciones)
A44: NOTA DE CONSOLIDACION
A45: Esta lista de 12 criterios resulta de fusionar una lista ampliada de 20 propuestas, de las cuales 8 duplicaban constructos ya cubiertos (fusionadas en C1, C3, C5, C6, C7, C8, C9, C12) y 2 aportaban ejes nuevos genuinos (C4: distincion proxy/variable latente; C11: trazabilidad del algoritmo de fusion del mismatch). No usar ambas listas simultaneamente en la extraccion: puntuar el mismo constructo dos veces infla artificialmente su peso relativo en la puntuacion total de calidad.

Sheet Extraccion_Estudios
A1: ID | B1: RQ Asociada | C1: Autor(es) y Anio | D1: Titulo | E1: Revista/Conferencia | F1: Base de Datos | G1: DOI/URL | H1: Tipo Estudio | I1: Cumple Inclusion | J1: Incluido Excluido | K1: Motivo Exclusion | L1: Eje | M1: Texto Completo Disponible | N1: C1 Trazabilidad de la mue | O1: C2 Validez de la medida d | P1: C3 Consistencia temporal | Q1: C4 Distincion entre varia | R1: C5 Transparencia e interp | S1: C6 Validacion externa/cru | T1: C7 Especificacion cuantit | U1: C8 Variabilidad inter/int | V1: C9 Alineacion con soporte | W1: C10 Transparencia en las l | X1: C11 Trazabilidad del algor | Y1: C12 Adecuacion del diseno | Z1: Puntuacion Total | AA1: Hallazgo Clave | AB1: Notas Limitaciones
A2: 11 | B2: RQ10 | C2: Simon et al. (2010) | D2: Pharmacokinetic Evidence for Suboptimal Treatment of Adrenal Insufficiency with Currently Available Hydrocortisone Tablets | E2: Clinical Pharmacokinetics, 49(7), 455-463 | F2: PubMed | G2: 10.2165/11531290-000000000-00000 | H2: Observacional prospectivo, modelo poblacional 1-compartimental (entrada de orden cero, eliminacion de primer orden), N=20 pacientes con insuficiencia suprarrenal | I2: Si | J2: Incluido | L2: Fisiologico/PK | M2: Si | N2: 2 | O2: 2 | P2: N/A | Q2: N/A | R2: N/A | S2: N/A | T2: 2 | U2: 2 | V2: N/A | W2: 2 | X2: N/A | Y2: 2 | Z2: =SUM(N2:Y2) -> 12 | AA2: [Pertenencia: Directa - mejor ajuste del set a RQ10] Modelo 1-compartimental con entrada de orden cero y eliminacion de primer orden en 20 pacientes con insuficiencia suprarrenal (8H/12M, edad media 53.1 anos). Parametros con variabilidad intersujeto explicita: duracion de absorcion 0.54h, volumen de distribucion 38.7L (CV 39.7%), aclaramiento 12.1L/h (CV 23.2%), error residual proporcional 32.3%. Los autores usan el modelo para simular 18 regimenes de dosificacion distintos; incluso el mejor regimen (10+5+5mg a las 07:30/12:00/16:30h) deja entre un 32% y 54% de pacientes simulados fuera del rango fisiologico objetivo segun la hora del dia. Es la cuantificacion mas directa y honesta del margen de error teorico de un modelo monocompartimental simplificado que existe en el set. | AB2: N pequeno (20) y poblacion heterogenea en etiologia (Addison, adrenalectomia bilateral) - la variabilidad reportada puede no ser generalizable a insuficiencia suprarrenal primaria pura. Texto completo no confirmado en los fragmentos disponibles (Springer, posible paywall) - verificar via acceso institucional.
A3: 12 | B3: RQ10 | C3: Melin et al. (2020) | D3: Pharmacokinetic/Pharmacodynamic Evaluation of Hydrocortisone Therapy in Pediatric Patients with Congenital Adrenal Hyperplasia | E3: The Journal of Clinical Endocrinology & Metabolism, 105(4), e1729-e1740 | F3: PubMed | G3: 10.1210/clinem/dgaa071 | H3: Observacional, modelo PK/PD poblacional 1-compartimental (NONMEM) con 17-OHP como biomarcador, N=30 pacientes pediatricos con hiperplasia suprarrenal congenita (7-17 anos) | I3: Si | J3: Incluido | L3: Fisiologico/PK | M3: Si | N3: 2 | O3: 2 | P3: N/A | Q3: N/A | R3: N/A | S3: N/A | T3: 2 | U3: 2 | V3: N/A | W3: 2 | X3: N/A | Y3: 2 | Z3: =SUM(N3:Y3) -> 12 | AA3: [Pertenencia: Directa] Modelo 1-compartimental con absorcion de primer orden (ka) y eliminacion lineal (CL/Vc) suficiente para describir los perfiles de cortisol plasmatico tras administracion oral e IV en 30 pacientes pediatricos con HSC. Reporta variabilidad interindividual explicita via coeficientes de variacion (CV%): 58.1% para el baseline de cortisol endogeno, con variabilidad residual mas alta tras administracion oral que IV (RUV oral notablemente mayor que RUV IV), evidencia directa de que la variabilidad en absorcion es mayor que la de eliminacion. Simula regimenes de 3 y 4 tomas diarias frente a rangos objetivo de cortisol y 17-OHP. | AB3: Poblacion pediatrica (7-17 anos) con HSC, no adultos con insuficiencia suprarrenal primaria - transferencia de dominio a justificar explicitamente por la autora, no abordada por los propios autores (17-OHP como biomarcador PD es especifico de HSC/deficit de 21-hidroxilasa, sin equivalente directo en insuficiencia suprarrenal primaria de otro origen). C10=2 (confirmado con texto completo, 26/08/2026): los autores declaran limitaciones sustantivas repartidas en la Discusion, no en seccion dedicada pero si explicitas y en varios puntos: (i) diferencias de PK por estatus puberal no se pudieron estimar por N insuficiente en cada subgrupo; (ii) 7/30 pacientes (23.3%) descartados del analisis PK/PD por concentraciones de 17-OHP bajo el limite de cuantificacion, con nota explicita de que un inmunoensayo mas sensible (LC-MS/MS) podria haber recuperado esos datos; (iii) reconocen que su diseno de simulacion no permite discriminar si dosis iguales o desiguales a lo largo del dia son preferibles; (iv) concluyen que se requiere un ensayo clinico prospectivo antes de confirmar beneficio clinico, es decir encuadran sus propios resultados como validacion funcional/simulacion y no como evidencia de eficacia clinica - coherente con el C12=2 ya asignado a esta fila.
A4: 13 | B4: RQ10 | C4: Werumeus Buning et al. (2017) | D4: Pharmacokinetics of oral hydrocortisone - Results and implications from a randomized controlled trial | E4: Metabolism, 71, 7-16 | F4: PubMed | G4: 10.1016/j.metabol.2017.02.005 | H4: Ensayo aleatorizado doble ciego cruzado, modelos poblacionales 1- y 2-compartimentales comparados, N=46 pacientes con insuficiencia suprarrenal secundaria | I4: Si | J4: Incluido | L4: Fisiologico/PK | M4: Si | N4: 2 | O4: 2 | P4: N/A | Q4: N/A | R4: N/A | S4: N/A | T4: 2 | U4: 2 | V4: N/A | W4: 1 | X4: N/A | Y4: 1 | Z4: =SUM(N4:Y4) -> 10 | AA4: [Pertenencia: Directa] Compara explicitamente modelos 1- y 2-compartimentales para cortisol libre plasmatico, cortisol total plasmatico y cortisol salival en 46 pacientes con dos dosis distintas de hidrocortisona oral. El modelo 1-compartimental describe mejor los datos que el 2-compartimental (relevante para justificar la simplificacion del TFM). Hallazgo central: la farmacocinetica de hidrocortisona puede diferir hasta 10 veces entre individuos (AUC24h), y doblar la dosis en metabolizadores rapidos no aumenta significativamente la exposicion durante gran parte del dia - evidencia directa de que el margen de error de un modelo poblacional simplificado sin ajuste individual puede ser sustancial. | AB4: Poblacion de insuficiencia suprarrenal SECUNDARIA (no primaria) - matiz relevante dado que el TFM no distingue explicitamente el subtipo. Texto completo no confirmado en los fragmentos disponibles (Elsevier/ScienceDirect, posible paywall) - C10 y C12 tentativos.
A5: 14 | B5: RQ10 | C5: Derendorf et al. (1991) | D5: Pharmacokinetics and Oral Bioavailability of Hydrocortisone | E5: The Journal of Clinical Pharmacology, 31(5), 473-476 | F5: PubMed | G5: 10.1002/j.1552-4604.1991.tb01906.x | H5: Estudio farmacocinetico clasico IV vs. oral, supresion endogena con dexametasona (tamano muestral no confirmado en fragmento disponible) | I5: Si | J5: Incluido | L5: Fisiologico/PK | M5: Si | N5: 1 | O5: 2 | P5: N/A | Q5: N/A | R5: N/A | S5: N/A | T5: 2 | U5: 0 | V5: N/A | W5: 0 | X5: N/A | Y5: 0 | Z5: =SUM(N5:Y5) -> 5 | AA5: [Pertenencia: Directa como fuente de parametros puntuales, no de variabilidad] Referencia clasica y ampliamente citada (aparece como cita bibliografica en practicamente todos los demas estudios PK de este set) que establece los parametros farmacocineticos canonicos de hidrocortisona oral tras supresion de cortisol endogeno con dexametasona: aclaramiento total 18 L/h, semivida de eliminacion 1.7h, volumen de distribucion 34L, biodisponibilidad oral media 96%, absorcion rapida con Cmax de ~300 ng/mL a la hora de la toma. Es la fuente mas citada del set para calibrar los valores puntuales (ka, ke, Tmax, Cmax, F) del modelo monocompartimental del TFM. | AB5: CRITICO: a diferencia de los otros 4 estudios, este NO reporta variabilidad inter/intraindividual (solo estima puntuales/medias) ni realiza analisis de sensibilidad - por eso puntua bajo en C8, C10 y C12 pese a ser la referencia canonica de parametros PK (C7=2). No usar como evidencia sobre el margen de error del modelo; usar solo para fijar los valores centrales de ka/ke/Tmax/Cmax/F. Tamano muestral no confirmado en el fragmento disponible (articulo de 1991, posible acceso solo por abstract/tabla - aplica la excepcion G4 de la RSL para parametros PK puntuales).
A6: 15 | B6: RQ10 | C6: Bornstein et al. (2016) | D6: Diagnosis and Treatment of Primary Adrenal Insufficiency: An Endocrine Society Clinical Practice Guideline | E6: The Journal of Clinical Endocrinology & Metabolism, 101(2), 364-389 | F6: PubMed | G6: 10.1210/jc.2015-1710 | H6: Guia de practica clinica basada en revision sistematica de evidencia con metodologia GRADE (excepcion G1-exc) | I6: Si | J6: Excluido | K6: E3 | L6: Fisiologico/PK | M6: Si | N6: N/A | O6: N/A | P6: N/A | Q6: N/A | R6: N/A | S6: N/A | T6: 0 | U6: 0 | V6: N/A | W6: 2 | X6: N/A | Y6: N/A | Z6: =SUM(N6:Y6) -> 2 | AA6: [Pertenencia: CONTEXTUAL, no Directa] Guia de la Endocrine Society que recomienda hidrocortisona 15-25 mg/dia (o cortisona acetato 20-35 mg/dia) en 2-3 tomas diarias para adultos, y ~8 mg/m2/dia en ninos, mas fludrocortisona una vez al dia (mediana 0.1 mg). No reporta parametros farmacocineticos cuantitativos (ka, ke, Tmax, Cmax, F) ni variabilidad inter/intraindividual - es una sintesis de recomendaciones clinicas de consenso, no un estudio de modelado PK. Su valor para RQ10 es normativo: ancla el rango de dosis fisiologicamente aceptado frente al cual contrastar la plausibilidad de las simulaciones del modelo monocompartimental del TFM. | AB6: Incluido via excepcion G1-exc (guia clinica de sociedad reconocida). Metodologia GRADE explicita con declaracion de ausencia de financiacion corporativa (transparencia alta, C10=2), pero no aporta evidencia cuantitativa de margen de error/sensibilidad (C7=0, C8=0) - no citar como fuente de parametros PK, solo como marco de dosificacion clinica de referencia. C1, C2 y C12 marcados N/A: no aplican a un documento de sintesis normativa sin muestra ni medida primaria propia.
A7: 30 | B7: RQ10 | C7: Allolio, B. (2015) | D7: Adrenal crisis | E7: European Journal of Endocrinology, 172(3), R115-R124 | F7: PubMed | G7: 10.1530/EJE-14-0824 | H7: Revision clinica | I7: Si | J7: Incluido | L7: Fisiologico/PK | M7: Si | N7: N/A | O7: N/A | P7: N/A | Q7: N/A | R7: N/A | S7: N/A | T7: 1 | U7: N/A | V7: 1 | W7: 1 | X7: N/A | Y7: N/A | Z7: =SUM(N7:Y7) -> 3 | AA7: Fue el ancla original de D_ref hasta la Seccion 6.1 (reanclaje a Kirschbaum et al. 1993); se mantiene registrada por trazabilidad historica de la decision, no como referencia vigente para ningun calculo actual del sistema. | AB7: ALERTA DE FRAMING: describe estres 'mayor' y recomendaciones de dosis clinica - el tipo de literatura que el framing obligatorio del proyecto pide evitar citar como si validara el sistema. Mantener solo como referencia de contraste/trazabilidad (asi lo declara ya Evolucion v11, Seccion 6.1), nunca como apoyo de un calculo vigente. Anadida en v4.
A8: 31 | B8: RQ10 | C8: Macheras, P., Symillides, M., & Reppas, C. (1992) | D8: On the Assessment of the Relative Magnitude of Rate Constants in the Linear Open One-Compartment Model | E8: Journal of Pharmaceutical Sciences, 81(12), 1231-1233 | F8: PubMed | G8: 10.1002/JPS.2600811223 | H8: Metodologico/farmacocinetico | I8: No | J8: Excluido | K8: OTRO | L8: Fisiologico/PK | M8: No | Z8: =SUM(N8:Y8) -> 0 | AB8: "No aporta evidencia directa a RQ10 — reclasificado como cita metodológica en Referencias_Metodologicas"
A9: 21 | B9: RQ11 | C9: Yavuz, Claassen & Kleinberg (2020) | D9: Lagged Correlations among Physiological Variables as Indicators of Consciousness in Stroke Patients | E9: AMIA Annual Symposium Proceedings, 2019:942-951 | F9: PubMed/PMC (PMC7153151) | G9: PMID: 32308891 | H9: Metodologico + validacion empirica en datos clinicos reales (UCI neurologica) | I9: Si | J9: Incluido | L9: Tecnico (Wearables/ML) | M9: Si | N9: 1 | O9: N/A | P9: 1 | Q9: 1 | R9: 2 | S9: 1 | T9: N/A | U9: N/A | V9: 2 | W9: 1 | X9: 2 | Y9: 2 | Z9: =SUM(N9:Y9) -> 13 | AA9: [Pertenencia: Directa] Introduce N2C2 (nonstationary normalized cross-correlation), metodo para detectar cambios en el lag entre variables fisiologicas correlacionadas en datos multimodales de UCI, disenado explicitamente para ser robusto al ruido. Validado en pacientes reales con hemorragia subaracnoidea: lags mas largos se asocian a menor nivel de consciencia. Es el precedente mas directo del set para el algoritmo de fusion/mismatch (C11). | AB9: No usa wearables de consumo ni datasets WESAD/SWELL; el ruido es de instrumentacion hospitalaria (monitorizacion continua en UCI neurologica), no de sensores ambulatorios. [Verificado con texto completo, 26/08/2026] C5=2 (revisado al alza desde 1): el algoritmo N2C2 es interpretable por diseno -- pipeline formalizado con ecuaciones explicitas (NCC, kernel tricube estirado, votacion de Borda con ventana deslizante), sin componente de caja negra, y codigo publicado en GitHub. Matiz metodologico: el criterio C5 esta formulado pensando en clasificadores ML supervisados con explicabilidad post-hoc (SHAP/LIME); aqui no aplica en sentido estricto porque no hay un modelo entrenado que opacar, sino un metodo estadistico basado en reglas explicitas -- la transparencia es estructural, no anadida a posteriori. No usar este caso como precedente de 'aplicabilidad general' de C5 a metodos no supervisados sin discutir esta distincion en el capitulo. C10=1 (confirmado, no revisado al alza): los autores reconocen puntualmente el tamano muestral reducido y la alta variabilidad individual ('Despite the small sample size and high individual variation...') y anotan trabajo futuro para clarificar el mecanismo causal de los lags, pero no incluyen una seccion de limitaciones dedicada ni discuten explicitamente: (a) generalizacion mas alla de pacientes SAH de un unico centro (Columbia University Medical Center, N=61), (b) validez ecologica de la Glasgow Coma Scale como medida de referencia de consciencia, ni (c) el umbral de significancia laxo (p<0.1, justificado por tamano muestral) como fuente potencial de falsos positivos en los pares de variables reportados.
A10: 22 | B10: RQ11 | C10: Meszlenyi, Hermann, Buza, Gal & Vidnyanszky (2017) | D10: Resting State fMRI Functional Connectivity Analysis Using Dynamic Time Warping | E10: Frontiers in Neuroscience, 11:75 | F10: PubMed/PMC (PMC5313507) | G10: 10.3389/fnins.2017.00075 | H10: Metodologico, validacion en datos simulados y datos reales de fMRI | I10: Si | J10: Incluido | L10: Tecnico (Wearables/ML) | M10: Si | N10: N/A | O10: N/A | P10: 0 | Q10: 1 | R10: N/A | S10: 1 | T10: N/A | U10: N/A | V10: N/A | W10: 1 | X10: 2 | Y10: 2 | Z10: =SUM(N10:Y10) -> 7 | AA10: [Pertenencia: Tangencial] Propone DTW en vez de correlacion de lag fijo para medir conectividad funcional en fMRI en reposo. Con datos simulados (SNR controlado) demuestran que DTW es menos sensible a ruido global superpuesto y detecta mejor desfases no estacionarios que la correlacion cruzada tradicional. | AB10: Dominio de aplicacion distinto (neuroimagen, no wearables); el tipo de ruido (artefactos de movimiento/hemodinamica) no es comparable al de sensores portatiles. No aborda CDSS (C9 N/A).
A11: 23 | B11: RQ11 | C11: Song, Wen, Li & Sun (2022) | D11: Robust Time Series Dissimilarity Measure for Outlier Detection and Periodicity Detection | E11: Proceedings of the 31st ACM CIKM (CIKM 22) | F11: ACM Digital Library | G11: 10.1145/3511808.3557686 | H11: Metodologico, propuesta algoritmica (RobustDTW) con validacion experimental | I11: Si | J11: Incluido | L11: Tecnico (Wearables/ML) | M11: Si | N11: N/A | O11: N/A | P11: N/A | Q11: N/A | R11: N/A | S11: 1 | T11: N/A | U11: N/A | V11: N/A | W11: 1 | X11: 2 | Y11: 1 | Z11: =SUM(N11:Y11) -> 5 | AA11: [Pertenencia: Contextual] Propone RobustDTW: estima tendencia y funcion de warping de forma alternante (temporal graph trend filtering) para reducir el efecto de ruido y outliers en el calculo de desfase entre series. Supera a variantes estandar de DTW en deteccion de outliers y periodicidad. | AB11: Dominio ajeno a biomedicina/fisiologia; sin discusion de interpretabilidad clinica ni de soporte a la decision. Aporta precedente tecnico de robustecimiento algoritmico, no evidencia de dominio.
A12: 24 | B12: RQ11 | C12: Boniol, Krishna, Bruel, Liu, Huang, Palpanas, Tsay, Elmore, Franklin & Paparrizos (2025) | D12: VUS: Effective and Efficient Accuracy Measures for Time-Series Anomaly Detection | E12: The VLDB Journal, 34(3), Art. 32 | F12: Springer Link / VLDB | G12: 10.1007/s00778-025-00907-x | H12: Metodologico - evaluacion sistematica de metricas de evaluacion | I12: Si | J12: Incluido | L12: Tecnico (Wearables/ML) | M12: Si | N12: N/A | O12: N/A | P12: N/A | Q12: N/A | R12: N/A | S12: 2 | T12: N/A | U12: N/A | V12: N/A | W12: 1 | X12: 1 | Y12: 2 | Z12: =SUM(N12:Y12) -> 6 | AA12: [Pertenencia: Tangencial - directa a la pregunta metodologica] Evalua sistematicamente la robustez de metricas de evaluacion (Precision, Recall, F1, AUC-ROC/PR y sus propias medidas VUS-ROC/VUS-PR) inyectando de forma controlada lag y ruido en series temporales. Demuestra que las metricas tradicionales varian mucho mas bajo estas perturbaciones que VUS. Responde de forma mas literal a RQ11 que ningun otro estudio del set. | AB12: No es biomedico ni aborda variables latentes fisiologicas ni framing de soporte a la decision clinica. Aporta el protocolo experimental (inyeccion controlada de ruido/lag + medicion de varianza) mas replicable para validar Risk(t).
A13: 25 | B13: RQ11 | C13: Ghorbani, Reinders & Tax (2024) | D13: PATE: Proximity-Aware Time Series Anomaly Evaluation | E13: Proceedings of the 30th ACM SIGKDD Conference (KDD 24) | F13: ACM Digital Library | G13: 10.1145/3637528.3671971 | H13: Metodologico - propuesta de metrica de evaluacion sensible a proximidad temporal | I13: Si | J13: Incluido | L13: Tecnico (Wearables/ML) | M13: Si | N13: N/A | O13: N/A | P13: N/A | Q13: N/A | R13: N/A | S13: 1 | T13: N/A | U13: N/A | V13: N/A | W13: 1 | X13: 1 | Y13: 1 | Z13: =SUM(N13:Y13) -> 4 | AA13: [Pertenencia: Contextual] Propone PATE: pondera la evaluacion de detecciones segun su proximidad temporal al evento real (deteccion temprana/tardia, tiempo de respuesta de inicio) en vez de exigir coincidencia exacta punto a punto. Argumenta que metricas tradicionales (F1 ajustado por punto) sobre/subestiman el desempeno cuando hay desfases de deteccion. | AB13: Centrado en deteccion de anomalias puntuales/rangos, no en el calculo continuo de un desfase entre dos curvas de demanda/cobertura. Complementa a VUS con un principio de penalizacion gradual (no binaria) de desfases.
A14: 34 | B14: RQ10 | C14: Debono, M., Ghobadi, C., Rostami-Hodjegan, A., Huatan, H., Campbell, M. J., Newell-Price, J., Darzy, B., Merke, D. P., Arlt, W., & Ross, R. J. (2009) | D14: Modified-release hydrocortisone to provide circadian cortisol profiles | E14: The Journal of Clinical Endocrinology & Metabolism, 94(5), 1548-1554 | F14: PubMed | G14: 10.1210/jc.2008-2380 | H14: Estudio clinico farmacocinetico cruzado y modelado de simulacion PK (in vivo / in silico) | I14: Si | J14: Incluido | L14: Fisiologico/PK | M14: Si | N14: 2 | O14: 2 | P14: 1 | Q14: 2 | R14: N/A | S14: N/A | T14: 2 | U14: 2 | V14: 1 | W14: 2 | X14: N/A | Y14: 2 | Z14: =SUM(N14:Y14) -> 16 | AA14: Fuente de los parametros de forma (Rm, Ramp, Tmin=00:18h, Tmax=08:32h) usados en Demand_circadian(t), Seccion 6.0. Reporta variabilidad interindividual en Cmax/Tmax superior al 35-40%, relevante para la limitacion de 'cinetica poblacional media, no individualizada' ya declarada en Coverage(t). | AB14: Ya extraida con puntuacion completa en la hoja 'Extraccion_Estudios Gemini y yo' (fila ID 12) pero ausente de la hoja canonica pese a sostener una decision cerrada central (6.0). Trasladada aqui en v4 conservando su puntuacion original de esa hoja.
A15: 36 | B15: RQ4 | C15: Gunnar, M., & Quevedo, K. (2007) | D15: The Neurobiology of Stress and Development | E15: Annual Review of Psychology, 58, 145-173 | F15: Gemini | G15: 10.1146/annurev.psych.58.110405.085605 | H15: Revision narrativa (neurobiologia del desarrollo) | I15: Si | J15: Incluido | L15: Fisiologico/PK | M15: Si | N15: N/A | O15: N/A | P15: 2 | Q15: N/A | R15: N/A | S15: N/A | T15: 1 | U15: N/A | V15: N/A | W15: N/A | X15: N/A | Y15: N/A | Z15: =SUM(N15:Y15) -> 3 | AA15: Fuente bibliografica de la ventana de 25 minutos de f(StressLoad(t)) (Seccion 6.0): documenta el tiempo hasta el pico de cortisol tras un estresor agudo (~25 min). Verificado con texto completo que el dato de semivida de recuperacion (60-70 min) citado por una fuente secundaria (PMC8139339) NO aparece en este articulo original. | AB15: Ejemplo explicito, dentro del propio proyecto, de deteccion de una cita secundaria mal atribuida - vale la pena mencionarlo en la memoria como evidencia de rigor en la revision bibliografica. Anadida en v4.
A16: 1 | B16: RQ4 | C16: Agorastos et al. (2019) | D16: Vagal effects of endocrine HPA axis challenges on resting autonomic activity assessed by heart rate variability measures in healthy humans | E16: Psychoneuroendocrinology, 102, 196-203 | F16: PubMed / ScienceDirect | G16: 10.1016/j.psyneuen.2018.12.017 | H16: Experimental - challenge farmacoendocrino intra-sujeto (metirapona/dexametasona), N=39 | I16: Si | J16: Incluido | L16: Fisiologico/PK | M16: Si | N16: 2 | O16: 2 | P16: 2 | Q16: 2 | R16: N/A | S16: N/A | T16: N/A | U16: 1 | V16: N/A | W16: 2 | X16: N/A | Y16: N/A | Z16: =SUM(N16:Y16) -> 11 | AA16: [Pertenencia: Directa] Unico estudio del set con manipulacion causal directa del eje HPA (supresion via dexametasona, estimulacion via metirapona) midiendo el efecto resultante sobre HRV vagal en 39 sujetos sanos. Invierte la direccion causal habitual de la literatura correlacional (HRV->cortisol) y demuestra HPA->vagal: metirapona redujo RMSSD, NN50%, HF% y aumento el coeficiente de escalado no lineal alpha_fast (indicando retirada vagal), mientras que dexametasona no tuvo efecto autonomico detectable. Evidencia mecanistica clave para justificar por que Demand(t) no puede leerse como funcion simple/directa de HRV: aqui es la perturbacion del eje HPA la que desplaza el tono vagal, no al reves. | AB16: CONFIRMADO CON TEXTO COMPLETO. N pequeno (39, tras cribado de 72 candidatos con criterios de exclusion muy estrictos) limita generalizacion de heterogeneidad interindividual (C8=1: diseno de medidas repetidas intra-sujeto con baseline Dia 1, pero sin cuantificar magnitud de variabilidad inter-individual mas alla de ajustar por edad/sexo/WHR/tabaquismo). C10 actualizado de 1 (tentativo) a 2: los autores declaran de forma explicita y extensa multiples limitaciones (medicion en un unico punto temporal 9h post-desafio que solo permite inferir efectos indirectos dada la vida media corta de metirapona ~2h; calidad de sueno no medida objetivamente; fase menstrual no controlada aunque si analizada post-hoc; ausencia de medida de respiracion pese a su efecto conocido sobre HRV). Direccionalidad a matizar en la RSL: este es un estudio de causalidad HPA->autonomico (perturbacion farmacologica del eje seguida de medicion de HRV en reposo), no de inferencia autonomico->HPA como requiere StressLoad(t) del TFM; citar con precision esa inversion para no sugerir que valida directamente el sentido de inferencia del proyecto. No usa wearables de consumo (ECG holter, protocolo de laboratorio con analisis manual en Kubios/MATLAB). No hay riesgo de fuga de datos (no hay ML ni particion de muestra).
A17: 2 | B17: RQ4 | C17: Mazgelyte et al. (2021) | D17: Association of Salivary Steroid Hormones and Their Ratios With Time-Domain Heart Rate Variability Indices in Healthy Individuals | E17: Journal of Medical Biochemistry, 40(2), 173-180 | F17: PubMed / PMC (PMC7982294) | G17: 10.5937/jomb0-26045 | H17: Observacional, repeated-measures (3 sesiones / 5 dias), N=40 | I17: Si | J17: Incluido | L17: Fisiologico/PK | M17: Si | N17: 2 | O17: 2 | P17: 1 | Q17: 2 | R17: N/A | S17: N/A | T17: N/A | U17: 2 | V17: N/A | W17: 2 | X17: N/A | Y17: N/A | Z17: =SUM(N17:Y17) -> 11 | AA17: [Pertenencia: Directa] Mide cortisol/cortisona/DHEA salivales (UHPLC-MS/MS) junto con RMSSD y pNN50 en 3 sesiones sobre 5 dias en 40 adultos sanos. Halla asociacion inversa entre tono vagal y cortisol/DHEA, pero el hallazgo central es de fiabilidad: la consistencia intraindividual (ICC) de los biomarcadores salivales puntuales es pobre-moderada (0.00-0.48), mientras que las metricas HRV son mas estables (0.52-0.65). El "ground truth" endocrino es, el mismo, menos fiable que el proxy autonomico. | AB17: Autores declaran de forma explicita: uso exclusivo de HRV en dominio temporal (sin componente de dominio frecuencial), medida indirecta de actividad 11b-HSD2, diseno observacional que impide causalidad. Maxima transparencia en limitaciones - citable con confianza. No usa wearables de consumo.
A18: 3 | B18: RQ4 | C18: Rotenberg & McGrath (2016) | D18: Inter-relation between autonomic and HPA axis activity in children and adolescents | E18: Biological Psychology, 117, 16-25 | F18: PubMed / PMC (PMC5731846) | G18: 10.1016/j.biopsycho.2016.01.015 | H18: Observacional transversal, N=201 (ninos/adolescentes) | I18: Si | J18: Incluido | L18: Fisiologico/PK | M18: Si | N18: 2 | O18: 2 | P18: 1 | Q18: 1 | R18: N/A | S18: N/A | T18: N/A | U18: 1 | V18: N/A | W18: 2 | X18: N/A | Y18: N/A | Z18: =SUM(N18:Y18) -> 9 | AA18: [Pertenencia: Directa] Cortisol salival (AUCAG, AUCI, maximo) + HRV de 24h via ECG ambulatorio (LF, HF, LF/HF) + Perceived Stress Scale en 201 sujetos. La interaccion entre modulacion simpatovagal y respuesta de cortisol al despertar explica mas varianza del estres percibido (2-4% adicional) que cualquiera de los dos sistemas por separado, apoyando el Modelo Aditivo de Bauer et al. (2002): hiperactivacion simetrica de ambos sistemas (alto LF/LF-HF + alto cortisol) se asocia a mayor estres percibido. Articulo de referencia mas citado en la literatura posterior sobre inter-relacion SNA-HPA (citado explicitamente por Bennett et al. 2024 y Agorastos et al. 2019, ambos tambien en este lote). | AB18: CONFIRMADO CON TEXTO COMPLETO. Poblacion pediatrica/adolescente (9-18 anos, en fase de adrenarquia): la maduracion del eje HPA en esa franja introduce un confusor que no aplica directamente a poblacion adulta con insuficiencia suprarrenal primaria - transferencia de dominio que la propia autoria del articulo NO discute (es un caveat introducido por esta revision, no una limitacion declarada por los autores; distincion relevante para no atribuirles un reconocimiento que no hicieron). C10 actualizado de 1 (tentativo) a 2: la Discusion incluye una seccion explicita de "Three study limitations" (diseno transversal que impide causalidad; la Perceived Stress Scale mide solo el ultimo mes, no estres cronico ni eventos vitales; HRV es gold standard para actividad parasimpatica pero solo medida indirecta de actividad simpatica). C3 mantenido en 1 (no en 2): el articulo describe extensamente en la Introduccion los mecanismos de coactivacion CRH-locus coeruleus y la diferencia de escalas temporales SNA (sinaptica, rapida) vs HPA (hormonal, minutos) como marco teorico, pero el analisis estadistico usa promedios diarios/agregados de 2 dias sin modelar el desfase temporal de forma analitica - coherente con Cvijetic/Mazgelyte de este mismo lote, que tampoco lo hacen, y se diferencia asi de Agorastos/Bennett que si razonan cuantitativamente sobre la cinetica del desfase (homogeneidad de criterio verificada dentro de RQ4). No usa wearables de consumo (ECG ambulatorio Vivometrics ± Kubios).
A19: 4 | B19: RQ4 | C19: Cvijetic et al. (2022) | D19: Diurnal Salivary Cortisol in Relation to Body Composition and Heart Rate Variability in Young Adults | E19: Frontiers in Endocrinology, 13, 831831 | F19: PubMed / PMC (PMC8959541) | G19: 10.3389/fendo.2022.831831 | H19: Observacional piloto, N=43 (estudiantes universitarios sanos) | I19: Si | J19: Incluido | L19: Fisiologico/PK | M19: Si | N19: 2 | O19: 2 | P19: 1 | Q19: 0 | R19: N/A | S19: N/A | T19: N/A | U19: 1 | V19: N/A | W19: 2 | X19: N/A | Y19: N/A | Z19: =SUM(N19:Y19) -> 8 | AA19: [Pertenencia: TANGENCIAL, no Directa - ver Notas] Cortisol salival en 3 puntos (protocolo minimo Adam & Kumari) + HRV via PPG en 43 universitarios. Encuentra asociacion entre predominancia simpatica (LF, LF/HF) y mayor tejido graso/menor masa osea, y entre menor masa muscular y menor LF/HF. La pregunta de investigacion primaria del estudio es composicion corporal, no la relacion SNA-HPA en si; el cruce cortisol-HRV es analisis secundario. | AB19: Reclasificado como Tangencial (no Directa) pese a medir ambas variables, porque su RQ primaria es composicion corporal. N pequeno (43, solo 4 hombres - desequilibrio de sexo severo no discutido a fondo). Sin registro de actividad fisica ni estres psicologico como covariables (limitacion reconocida por los autores). No distingue explicitamente proxy vs. variable latente (C4=0). No usa wearables de consumo.
A20: 5 | B20: RQ4 | C20: Bennett, Tomas & Fitzgerald (2024) | D20: Relationship between heart rate variability and differential patterns of cortisol response to acute stressors in mid-life adults: A data-driven investigation | E20: Stress and Health, 40(3), e3327 | F20: PubMed / Wiley | G20: 10.1002/smi.3327 | H20: Observacional, modelado de trayectorias (latent growth mixture modelling), N=386 (cohorte MIDUS) | I20: Si | J20: Incluido | L20: Fisiologico/PK | M20: Si | N20: 2 | O20: 2 | P20: 2 | Q20: 1 | R20: N/A | S20: N/A | T20: N/A | U20: 2 | V20: N/A | W20: 2 | X20: N/A | Y20: N/A | Z20: =SUM(N20:Y20) -> 11 | AA20: [Pertenencia: Directa] Mayor N del set (386, cohorte MIDUS Refresher). Aborda de frente la inconsistencia entre estudios individuales sobre la relacion HRV-cortisol mediante latent growth mixture modelling (LGMM): identifica 3 trayectorias de cortisol ante estres de laboratorio (prototipica 80%, decline 7%, rise 13%) y muestra que la asociacion HRV-cortisol post-estres solo aparece en el subgrupo "prototipico" (r=0.19, p<.001); en los subgrupos atipicos la relacion desaparece por completo. Evidencia empirica directa de que Demand(t) no puede tratarse como funcion uniforme de senales autonomicas: hay heterogeneidad de fenotipos de respuesta que una relacion lineal simple HR->Demand no captura. | AB20: CONFIRMADO CON TEXTO COMPLETO (via repositorio, no version editorial). C10 actualizado de 1 (tentativo) a 2: la seccion de limitaciones es explicita y sustantiva (protocolo carece de fase anticipatoria de estres, por lo que no permite estudiar HRV anticipatoria por separado; muestra racialmente homogenea, >80% blanca; edad media alta, 49 anos, con HRV conocida por decrecer con la edad, limitando generalizacion a poblacion mas joven). C4 se mantiene en 1 (no sube a 2): LGMM modela formalmente una variable de clase LATENTE (pertenencia a trayectoria de cortisol no observada, inferida desde los datos) - hay una coincidencia terminologica interesante con el concepto de variable latente del TFM, pero se trata de heterogeneidad de forma de la trayectoria de cortisol (una variable SI medida directamente), no de la distincion proxy-wearable/demanda-latente que pide el criterio C4; matiz a explicitar si se cita en la memoria para no sobrerrepresentar el paralelismo. Riesgo de sobreclaim a vigilar: las relaciones reportadas son correlacionales y los propios autores lo declaran explicitamente ("results... are correlational and do not imply causation") - no citar como evidencia causal HRV->cortisol. No usa wearables de consumo (ECG continuo intra-laboratorio, RMSSD). No hay riesgo de fuga de datos (no hay ML ni particion train/test).
A21: 28 | B21: RQ4 | C21: Hahner, S., Loeffler, M., Bleicken, B., Drechsler, C., Milovanovic, D., Fassnacht, M., Ventz, M., Quinkler, M., & Allolio, B. (2010) | D21: Epidemiology of adrenal crisis in chronic adrenal insufficiency: the need for new prevention strategies | E21: European Journal of Endocrinology, 162, 597-602 | F21: PubMed | G21: 10.1530/EJE-09-0884 | H21: Estudio observacional multicentrico (cuestionario), pacientes con insuficiencia suprarrenal primaria/secundaria | I21: Si | J21: Incluido | L21: Fisiologico/PK | M21: Si | N21: 2 | O21: N/A | P21: N/A | Q21: N/A | R21: N/A | S21: N/A | T21: N/A | U21: 1 | V21: 2 | W21: 2 | X21: N/A | Y21: N/A | Z21: =SUM(N21:Y21) -> 7 | AA21: Estres psiquico documentado como causa precipitante de crisis adrenal en 3,3% (IS primaria) y 3,6% (IS secundaria) de los casos - cifra exacta ya usada en la Seccion 3 (motivacion) de Evolucion v11. | AB21: Ya verificada con texto completo por la autora el 27/07/2026 (nota presente en la hoja 'Extraccion_Estudios Gemini y yo', fila con ID 31). Corrige una cifra previa incorrecta (~20%) manejada en una version anterior del proyecto. Trasladada a la hoja canonica en v4.
A22: 29 | B22: RQ4 | C22: National Institute for Health and Care Excellence (NICE) (2024) | D22: Adrenal insufficiency: identification and management | E22: NICE guideline NG243 | F22: nice.org.uk | G22: https://www.nice.org.uk/guidance/ng243 | H22: Guia de practica clinica | I22: Si | J22: Excluido | K22: E3 | L22: Fisiologico/PK | M22: Si | N22: N/A | O22: N/A | P22: N/A | Q22: N/A | R22: N/A | S22: N/A | T22: N/A | U22: N/A | V22: 2 | W22: 2 | X22: N/A | Y22: N/A | Z22: =SUM(N22:Y22) -> 4 | AA22: Guia de referencia que contempla explicitamente el ajuste de dosis ante estres psicologico agudo (a diferencia de Bornstein et al. 2016, centrada en estresores fisicos) - fuente directa de la motivacion del TFM (Seccion 3). | AB22: Verificada con PDF completo (publicada 28/08/2024, 63 paginas) el 24/08/2026. No es un estudio primario en sentido estricto: no aplica la mayoria de los 12 criterios de calidad disenados para estudios empiricos; se puntua solo lo aplicable (C9, C10). Anadida en v4.
A23: 16 | B23: RQ7 | C23: Pathmanathan et al. (2024) | D23: Credibility assessment of in silico clinical trials for medical devices | E23: PLOS Computational Biology, 20(8), e1012289 | F23: PubMed / PMC (PMC11309390) | G23: 10.1371/journal.pcbi.1012289 | H23: Revision metodologica / propuesta de framework, autoria FDA (Center for Devices and Radiological Health) | I23: Si | J23: Incluido | L23: Tecnico (Wearables/ML) | M23: Si | N23: 2 | O23: N/A | P23: N/A | Q23: N/A | R23: N/A | S23: 2 | T23: N/A | U23: N/A | V23: 2 | W23: 2 | X23: N/A | Y23: 2 | Z23: =SUM(N23:Y23) -> 10 | AA23: [Pertenencia: Directa] Revision de ensayos clinicos in silico (ISCT) reales para dispositivos medicos, cubriendo pacientes virtuales subject-specific vs. "sinteticos" puros, e incorporando un framework jerarquico de credibilidad basado en ASME V&V 40 y la guia de la FDA sobre modelado computacional. Distingue explicitamente verificacion, validacion y cuantificacion de incertidumbre (V&V+UQ) como pilares separados, y propone un flujo de trabajo de credibilidad adaptable segun el nivel de riesgo de la decision que el modelo informa. Es la referencia mas directamente aplicable del set al marco metodologico de validacion funcional del TFM. | AB23: Autoria mayoritariamente de la FDA (CDRH) - perspectiva regulatoria de EEUU, puede no reflejar estandares equivalentes de otras agencias (EMA, etc.). Comparte 3 autores y el mismo proyecto (ISCT Enrichment Project) con el estudio de Aycock et al. (2024) incluido tambien en esta RQ - no tratar como dos fuentes plenamente independientes en la discusion, sino como dos piezas complementarias del mismo esfuerzo FDA-industria.
A24: 17 | B24: RQ7 | C24: Aycock et al. (2024) | D24: Toward trustworthy medical device in silico clinical trials: a hierarchical framework for establishing credibility and strategies for overcoming key challenges | E24: Frontiers in Medicine, 11, 1433372 | F24: PubMed / PMC (PMC11346031) | G24: 10.3389/fmed.2024.1433372 | H24: Revision metodologica / propuesta de framework jerarquico, proyecto FDA-industria (ISCT Enrichment Project) | I24: Si | J24: Incluido | L24: Tecnico (Wearables/ML) | M24: Si | N24: 2 | O24: N/A | P24: N/A | Q24: N/A | R24: N/A | S24: 2 | T24: N/A | U24: N/A | V24: 1 | W24: 2 | X24: N/A | Y24: 2 | Z24: =SUM(N24:Y24) -> 9 | AA24: [Pertenencia: Directa] Propone evaluar la credibilidad de un ISCT de forma jerarquica: primero recolectando evidencia de credibilidad para cada submodelo (modelo de paciente virtual, modelo del dispositivo, modelo de mapeo a resultado clinico) de forma aislada, antes de establecer la credibilidad del ISCT completo. Identifica retos comunes para demostrar credibilidad (generacion de cohortes virtuales, modelos de decision clinica, mapeo a resultados) e ilustra el enfoque con un caso hipotetico completo en apendice - un precedente metodologico directo para descomponer la validacion del sistema hibrido del TFM (StressLoad-Demand-Coverage-Risk) en componentes evaluables por separado. | AB24: Mismo proyecto y solapamiento de autoria con Pathmanathan et al. (2024) en esta misma RQ (ver nota cruzada). Enfocado en dispositivos medicos en sentido amplio, no en CDSS de software puro - la transferencia de dominio a un sistema de software (no un dispositivo fisico) requiere justificacion explicita en la RSL.
A25: 18 | B25: RQ7 | C25: Cobelli & Kovatchev (2023) | D25: Developing the UVA/Padova Type 1 Diabetes Simulator: Modeling, Validation, Refinements, and Utility | E25: Journal of Diabetes Science and Technology, 17(6), 1493-1505 | F25: PubMed / PMC (PMC10658679) | G25: 10.1177/19322968231195081 | H25: Revision historica/tecnica del desarrollo y validacion de un simulador in silico, aceptado por la FDA como sustituto de ensayos en animales | I25: Si | J25: Incluido | L25: Tecnico (Wearables/ML) | M25: Si | N25: 2 | O25: N/A | P25: N/A | Q25: N/A | R25: N/A | S25: 2 | T25: N/A | U25: N/A | V25: 2 | W25: 2 | X25: N/A | Y25: 2 | Z25: =SUM(N25:Y25) -> 10 | AA25: [Pertenencia: Directa - precedente regulatorio mas fuerte del set] En 2008 la FDA acepto, de forma sin precedentes, un simulador computacional (300 "sujetos" virtuales con parametros metabolicos distintos) como SUSTITUTO de los ensayos en animales para probar algoritmos de control en lazo cerrado de insulina (paramo directo al Risk(t)/Coverage(t) del TFM: es literalmente un CDSS de dosificacion hormonal validado solo con escenarios sinteticos antes de pasar a humanos). El articulo documenta la evolucion del simulador (S2008 -> S2013 -> version multi-dia) y como sus limitaciones de dominio de validez (inicialmente solo escenarios de una comida) se fueron ampliando progresivamente. De los algoritmos desarrollados asi, 6 llegaron a uso clinico real hacia 2023. | AB25: Dominio de aplicacion es diabetes/insulina, no insuficiencia suprarrenal/hidrocortisona - es un precedente METODOLOGICO y REGULATORIO trasladable, no evidencia fisiologica directa sobre el eje HPA. Citar con esa salvedad explicita: "por analogia con..." no "en insuficiencia suprarrenal...". Autoria de los propios desarrolladores del simulador - posible sesgo de autopromocion a considerar al leer las secciones de utilidad/exito clinico.
A26: 19 | B26: RQ7 | C26: Chen et al. (2019) | D26: The validity of synthetic clinical data: a validation study of a leading synthetic data generator (Synthea) using clinical quality measures | E26: BMC Medical Informatics and Decision Making, 19, 44 | F26: PubMed / PMC | G26: 10.1186/s12911-019-0793-0 | H26: Estudio de validacion empirica, cohorte sintetica de 1.2 millones de pacientes (Massachusetts, generador Synthea) comparada contra tasas reales publicadas | I26: Si | J26: Incluido | L26: Tecnico (Wearables/ML) | M26: Si | N26: 2 | O26: N/A | P26: N/A | Q26: N/A | R26: N/A | S26: 2 | T26: N/A | U26: N/A | V26: 1 | W26: 2 | X26: N/A | Y26: 1 | Z26: =SUM(N26:Y26) -> 8 | AA26: [Pertenencia: Directa] Compara 4 medidas de calidad clinica calculadas sobre una cohorte sintetica de 1.2 millones de pacientes generada por Synthea frente a las tasas reales publicadas de Massachusetts y nacionales. Hallazgo critico y cuantificado: la mortalidad a 30 dias simulada tras exacerbacion de EPOC fue 0.7% frente al 7-8% real reportado - un desfase de un orden de magnitud. Los autores concluyen que Synthea modela bien la demografia y la probabilidad de recibir servicios, pero NO modela desviaciones de la practica clinica estandar ni sus resultados asociados. Es la cuantificacion empirica mas concreta del set sobre cuanto puede desviarse un escenario sintetico de la realidad si no se disena con ese objetivo explicito. | AB26: Evalua un generador de datos sinteticos general (registros electronicos), no un CDSS especifico - la relevancia para RQ7 es indirecta pero la cuantificacion del desfase es la evidencia empirica mas concreta del set sobre limites de validez externa. No usar como evidencia sobre CDSS de dosificacion hormonal especificamente.
A27: 20 | B27: RQ7 | C27: Koul, Duran & Hernandez-Boussard (2025) | D27: Synthetic data, synthetic trust: navigating data challenges in the digital revolution | E27: The Lancet Digital Health, 7(11), 100924 | F27: PubMed / PMC (PMC12778113) | G27: 10.1016/j.landig.2025.100924 | H27: Viewpoint/perspectiva editorial (no estudio empirico primario) | I27: Si | J27: Incluido | L27: Tecnico (Wearables/ML) | M27: Si | N27: N/A | O27: N/A | P27: N/A | Q27: N/A | R27: N/A | S27: N/A | T27: N/A | U27: N/A | V27: 1 | W27: 2 | X27: N/A | Y27: N/A | Z27: =SUM(N27:Y27) -> 3 | AA27: [Pertenencia: CONTEXTUAL, no Directa] Viewpoint que introduce el concepto de "confianza sintetica" (synthetic trust): la confianza injustificada en modelos entrenados o validados con datos artificiales que no preservan validez clinica ni representatividad demografica. Argumenta que el uso creciente de datos sinteticos en IA medica puede propagar sesgos, acelerar la degradacion de modelos y comprometer la generalizacion entre poblaciones. No aporta evidencia empirica propia, pero articula con precision el riesgo conceptual central que el TFM debe reconocer explicitamente al basar su validacion funcional en escenarios sinteticos. | AB27: Es un articulo de opinion/perspectiva (Viewpoint), no un estudio primario - no aporta evidencia empirica propia (C1, C6 y C12 marcados N/A por no aplicar a este tipo de articulo). Incluido pese a su naturaleza no empirica porque responde directamente a la segunda mitad de RQ7 ("que limitaciones de validez externa conllevan"), que ningun otro estudio del set aborda de forma tan centrada y explicita.
A28: 6 | B28: RQ9 | C28: Dunn et al. (2021) | D28: Wearable sensors enable personalized predictions of clinical laboratory measurements | E28: Nature Medicine, 27(6), 1105-1112 | F28: PubMed | G28: 10.1038/s41591-021-01339-0 | H28: Observacional longitudinal, modelos Random Forest y Lasso, cohorte wearables Stanford | I28: Si | J28: Incluido | L28: Tecnico (Wearables/ML) | M28: Si | N28: 2 | O28: N/A | P28: N/A | Q28: 2 | R28: 2 | S28: 2 | T28: N/A | U28: 2 | V28: 2 | W28: 2 | X28: N/A | Y28: 2 | Z28: =SUM(N28:Y28) -> 16 | AA28: [Pertenencia: Directa, como precedente metodologico] Confirmado con texto completo (PMC author manuscript, HHS Public Access). Senales de wearables de consumo (HR, temperatura corporal, actividad electrodermica, movimiento) predicen multiples parametros de laboratorio clinico (hematocrito, hemoglobina, recuento de eritrocitos y plaquetas con mejor desempeno) usando Random Forest, Lasso y CCA regularizada, con validacion leave-one-person-out (LOPOCV) explicita. Los modelos personalizados (media + pendiente individual) explican en promedio un 43% mas de varianza que los modelos poblacionales - precedente metodologico directo para la personalizacion de Demand(t)/Coverage(t) en el caso n-of-1 del TFM. Referencia de mayor perfil editorial del set (Nature Medicine). | AB28: Texto completo confirmado (PDF HHS Public Access, Nat Med 2021). C10 actualizado de tentativo (1) a confirmado (2): la Discusion incluye limitaciones sustantivas y especificas -- tamano de cohorte iPOP limitado (n=54), generalizabilidad condicionada al entrenamiento en la cohorte de destino, y sesgo de seleccion en el dataset SEHR (los pacientes con mas visitas clinicas tienden a estar mas enfermos, Fig. Ext. 2b). C2 corregido de 2 a N/A: el estudio no predice ningun analito endocrino/glucocorticoide -- predice un panel amplio de labs clinicos (hematologicos, metabolicos, etc.); el criterio C2 (validez de la medida de referencia ENDOCRINA) no es aplicable a este diseno, y puntuarlo como 2 sobrestimaba su relevancia directa para RQ9. No infiere cortisol/eje HPA en ningun momento -- sigue siendo util unicamente como precedente metodologico (RF/Lasso, personalizacion, LOPOCV) para el paradigma 'wearable -> variable de laboratorio latente', no como evidencia fisiologica sobre HPA. [Homogeneidad C9/C12 aplicada 25/08/2026, decision de la autora: estos dos criterios son transversales, no exclusivos de estudios PK/fusion, y se puntuan ahora en todas las filas tecnicas de RQ9 en vez de N/A.] C9=2: framing explicito de soporte a la decision con limite claro de responsabilidad -- cita textual: 'Presently, we do not anticipate diagnostic use of the current models; however, they can be used to suggest further clinical testing'. Es el ejemplo mas limpio del set de framing CDSS correcto. C12=2: distingue implicitamente validacion funcional de eficacia clinica (mismo pasaje anterior) y aporta analisis de sensibilidad genuino -- comparacion sistematica de ventanas temporales (1 dia/3 dias/1 semana/1 mes/todos los datos, Fig. 4a) y de complejidad de modelo (univariante/multivariante/Lasso/RF/CCA), ademas de bootstrap de 1000 repeticiones para intervalos de confianza.
A29: 7 | B29: RQ9 | C29: Saskovets, Lohachov & Liang (2025) | D29: Cortisol Estimation Using Wearable Wristbands: Comparing Multilevel Modelling and Machine Learning | E29: Proceedings of the 2025 IEEE 14th Global Conference on Consumer Electronics (GCCE 2025), Osaka, Japon | F29: IEEE Xplore / ResearchGate | G29: Pendiente de DOI IEEE definitivo (verificar en IEEE Xplore tras publicacion de actas) | H29: Observacional, comparacion Random Forest vs. Modelado Multinivel (MMM), N=175 muestras de cortisol / 5 fases experimentales | I29: Si | J29: Incluido | L29: Tecnico (Wearables/ML) | M29: Si | N29: 1 | O29: 1 | P29: N/A | Q29: 2 | R29: 2 | S29: 2 | T29: N/A | U29: 2 | V29: 0 | W29: 0 | X29: N/A | Y29: 0 | Z29: =SUM(N29:Y29) -> 10 | AA29: [Pertenencia: Directa] Confirmado con texto completo. Compara Random Forest frente a Modelado Multinivel Multivariante (MMM) para predecir cortisol a partir de HR, HRV, actividad electrodermica, aceleracion y temperatura cutanea captados por wearable de muneca (Empatica E4, N=35 participantes, 175 muestras de cortisol salival en 5 fases). RF obtiene R2=0.510 (vs. 0.433 de MMM) con validacion GroupKFold de 3 folds agrupada por participante (evita fuga de datos entre sujetos, confirmado en texto completo); EDA aporta el 60% de la importancia de caracteristicas, seguida de HR. El MMM modela explicitamente varianza inter-individual mediante intercepto y pendientes aleatorias por participante (EDA, HR, HRV, TEMP) - ejemplo directo de manejo de variabilidad inter-individual (C8). Trade-off explicito precision-vs-interpretabilidad, exactamente el dilema central de RQ9. | AB29: Texto completo confirmado (IEEE GCCE 2025, 2 paginas). Tres correcciones tras lectura completa: (1) C10 de tentativo (1) a confirmado (0): la Conclusion no contiene una seccion de limitaciones sustantiva -- solo menciona de forma generica 'small sample sizes and multimodal signal variability pose significant challenges' en la introduccion y cierra con framing de trabajo futuro ('explore hybrid modeling approaches'), sin discutir el R2 moderado (0.510), el riesgo de sobreajuste con solo 3-fold y 175 muestras, ni la seleccion de la ventana de 1 minuto (que los propios autores optimizaron por correlacion, riesgo de sesgo optimista no discutido). (2) C1 de 2 a 1: el protocolo de induccion de estres (IMPRO, habla improvisada) no se describe en este articulo -- se remite integramente a la referencia [10] (Saskovets et al. 2024, bioRxiv), por lo que la trazabilidad no es autocontenida. (3) C2 de 2 a 1: no se especifica metodo de ensayo del cortisol salival ni control explicito del timing circadiano de las 175 muestras -- el criterio exige ambos elementos. DOI de las actas IEEE sigue sin confirmar definitivamente (ver celda G29). [Homogeneidad C9/C12 aplicada 25/08/2026.] C9=0: no hay ningun encuadre explicito como CDSS ni declaracion de limites de responsabilidad clinica -- el articulo se limita a mencionar aplicaciones en 'health technology and personalized interventions' sin matizar el alcance. C12=0: validacion reducida a un unico split de 3-fold GroupKFold, sin intervalos de confianza/bootstrap, sin analisis de sensibilidad frente a ruido o variacion de parametros, y sin distinguir explicitamente validacion funcional de eficacia clinica real.
